Workbook

Sheet Table&Findings
A1: Table 1. Key characteristics of the analyzed bus feeds
A3: Quantity | B3: Value | C3: 95% CI low | D3: 95% CI high | E3: Feeds (n) | F3: Data column
A4: Analyzed feeds | B4: =COUNTA(feed_data_v2!$A$2:$A$1866) -> 1865 | F4: feed_id
A5: Countries | B5: =ROUND(SUMPRODUCT((feed_data_v2!$C$2:$C$1866<>"")/COUNTIF(feed_data_v2!$C$2:$C$1866,feed_data_v2!$C$2:$C$1866&"")),0) -> 78 | F5: country
A6: i) Resolution
A7: Feeds with at least 95% of inter-stop travel times on a whole minute | B7: =(COUNTIF(feed_data_v2!$I$2:$I$1866,">=0.95"))/E7 -> 0.63270777 | C7: =MAX(0,B7-1.96*SQRT(B7*(1-B7)/E7)) -> 0.61082894 | D7: =MIN(1,B7+1.96*SQRT(B7*(1-B7)/E7)) -> 0.65458661 | E7: =COUNT(feed_data_v2!$I$2:$I$1866) -> 1865 | F7: share_travel_times_whole_minute
A8: Feeds with fewer than 5% of inter-stop travel times on a whole minute | B8: =(COUNTIF(feed_data_v2!$I$2:$I$1866,"<0.05"))/E8 -> 0.20857909 | C8: =MAX(0,B8-1.96*SQRT(B8*(1-B8)/E8)) -> 0.19013931 | D8: =MIN(1,B8+1.96*SQRT(B8*(1-B8)/E8)) -> 0.22701887 | E8: =COUNT(feed_data_v2!$I$2:$I$1866) -> 1865 | F8: share_travel_times_whole_minute
A9: Feeds with at least 95% of stop times on a whole minute | B9: =(COUNTIF(feed_data_v2!$J$2:$J$1866,">=0.95"))/E9 -> 0.63753351 | C9: =MAX(0,B9-1.96*SQRT(B9*(1-B9)/E9)) -> 0.61571616 | D9: =MIN(1,B9+1.96*SQRT(B9*(1-B9)/E9)) -> 0.65935087 | E9: =COUNT(feed_data_v2!$J$2:$J$1866) -> 1865 | F9: share_stop_times_whole_minute
A10: Median feed: share of stop times on a whole minute | B10: =MEDIAN(feed_data_v2!$J$2:$J$1866) -> 1 | E10: =COUNT(feed_data_v2!$J$2:$J$1866) -> 1865 | F10: share_stop_times_whole_minute
A11: ii) Interpolation
A12: Feeds that populate the timepoint field | B12: =COUNTIF(feed_data_v2!$K$2:$K$1866,"declared") -> 760 | E12: =COUNTA(feed_data_v2!$A$2:$A$1866) -> 1865 | F12: timepoint_status
A13: Median share of stop times flagged approximate | B13: =MEDIAN(feed_data_v2!$L$2:$L$1866) -> 0.79299647 | C13: =SMALL(feed_data_v2!$L$2:$L$1866,MAX(1,FLOOR(E13/2-1.96*SQRT(E13)/2,1))) -> 0.77919217 | D13: =SMALL(feed_data_v2!$L$2:$L$1866,MIN(E13,CEILING(E13/2+1.96*SQRT(E13)/2,1))) -> 0.8042623 | E13: =COUNT(feed_data_v2!$L$2:$L$1866) -> 760 | F13: approximate_share
A14: Median share of testable approximate times on the interpolation line (lower bound) | B14: =MEDIAN(feed_data_v2!$Q$2:$Q$1866) -> 0.42297405 | C14: =SMALL(feed_data_v2!$Q$2:$Q$1866,MAX(1,FLOOR(E14/2-1.96*SQRT(E14)/2,1))) -> 0.30888769 | D14: =SMALL(feed_data_v2!$Q$2:$Q$1866,MIN(E14,CEILING(E14/2+1.96*SQRT(E14)/2,1))) -> 0.5854792 | E14: =COUNT(feed_data_v2!$Q$2:$Q$1866) -> 444 | F14: share_approx_on_line
A15: Median share of testable exact timepoints on the interpolation line | B15: =MEDIAN(feed_data_v2!$S$2:$S$1866) -> 0.0047231512 | C15: =SMALL(feed_data_v2!$S$2:$S$1866,MAX(1,FLOOR(E15/2-1.96*SQRT(E15)/2,1))) -> 0 | D15: =SMALL(feed_data_v2!$S$2:$S$1866,MIN(E15,CEILING(E15/2+1.96*SQRT(E15)/2,1))) -> 0.032223416 | E15: =COUNT(feed_data_v2!$S$2:$S$1866) -> 118 | F15: share_timepoints_on_line
A16: Feeds with most stop times flagged approximate and at least 95% of them on whole minutes | B16: =(COUNTIFS(feed_data_v2!$L$2:$L$1866,">0.5",feed_data_v2!$N$2:$N$1866,">=0.95"))/E16 -> 0.28026316 | C16: =MAX(0,B16-1.96*SQRT(B16*(1-B16)/E16)) -> 0.24833167 | D16: =MIN(1,B16+1.96*SQRT(B16*(1-B16)/E16)) -> 0.31219465 | E16: =COUNTIF(feed_data_v2!$K$2:$K$1866,"declared") -> 760 | F16: approximate_share, share_approx_whole_minute
A17: Correlation of sub-minute precision with approximate share | B17: {=CORREL(1-feed_data_v2!$J$2:$J$1866,feed_data_v2!$L$2:$L$1866)} -> 0.3850241 | E17: =COUNT(feed_data_v2!$L$2:$L$1866) -> 760 | F17: share_stop_times_whole_minute, approximate_share
A18: iii) Time of day (peaks 07:00-09:00 and 16:00-18:00, midday 10:00-14:00)
A19: Median increase in scheduled bus travel time, peaks over midday | B19: {=MEDIAN(IF(feed_data_v2!$Z$2:$Z$1866>=20,feed_data_v2!$AA$2:$AA$1866))} -> 0.0014465411 | C19: {=SMALL(IF(feed_data_v2!$Z$2:$Z$1866>=20,feed_data_v2!$AA$2:$AA$1866),MAX(1,FLOOR(E19/2-1.96*SQRT(E19)/2,1)))} -> 0.00062025611 | D19: {=SMALL(IF(feed_data_v2!$Z$2:$Z$1866>=20,feed_data_v2!$AA$2:$AA$1866),MIN(E19,CEILING(E19/2+1.96*SQRT(E19)/2,1)))} -> 0.0023021355 | E19: =COUNTIFS(feed_data_v2!$Z$2:$Z$1866,">=20") -> 1546 | F19: bus_peak_midday_increase, feeds with n_bus_peak_midday_segments >= 20
A20: Feeds whose peak and midday bus travel times differ by less than 2% | B20: =(COUNTIFS(feed_data_v2!$Z$2:$Z$1866,">=20",feed_data_v2!$AA$2:$AA$1866,">-0.02",feed_data_v2!$AA$2:$AA$1866,"<0.02"))/E20 -> 0.68111255 | C20: =MAX(0,B20-1.96*SQRT(B20*(1-B20)/E20)) -> 0.65788093 | D20: =MIN(1,B20+1.96*SQRT(B20*(1-B20)/E20)) -> 0.70434417 | E20: =COUNTIF(feed_data_v2!$Z$2:$Z$1866,">=20") -> 1546 | F20: bus_peak_midday_increase, feeds with n_bus_peak_midday_segments >= 20
A21: Feeds with a segregated mode: median bus increase | B21: {=MEDIAN(IF(feed_data_v2!$AF$2:$AF$1866=TRUE,feed_data_v2!$AA$2:$AA$1866))} -> 0.018773086 | C21: {=SMALL(IF(feed_data_v2!$AF$2:$AF$1866=TRUE,feed_data_v2!$AA$2:$AA$1866),MAX(1,FLOOR(E21/2-1.96*SQRT(E21)/2,1)))} -> 0.011999512 | D21: {=SMALL(IF(feed_data_v2!$AF$2:$AF$1866=TRUE,feed_data_v2!$AA$2:$AA$1866),MIN(E21,CEILING(E21/2+1.96*SQRT(E21)/2,1)))} -> 0.026477033 | E21: =COUNTIFS(feed_data_v2!$AF$2:$AF$1866,TRUE) -> 203 | F21: bus_peak_midday_increase, feeds with has_peak_midday_baseline
A22: Feeds with a segregated mode: median segregated-mode increase | B22: {=MEDIAN(IF(feed_data_v2!$AF$2:$AF$1866=TRUE,feed_data_v2!$AG$2:$AG$1866))} -> 0.00067069081 | C22: {=SMALL(IF(feed_data_v2!$AF$2:$AF$1866=TRUE,feed_data_v2!$AG$2:$AG$1866),MAX(1,FLOOR(E22/2-1.96*SQRT(E22)/2,1)))} -> 0 | D22: {=SMALL(IF(feed_data_v2!$AF$2:$AF$1866=TRUE,feed_data_v2!$AG$2:$AG$1866),MIN(E22,CEILING(E22/2+1.96*SQRT(E22)/2,1)))} -> 0.00229909 | E22: =COUNTIFS(feed_data_v2!$AF$2:$AF$1866,TRUE) -> 203 | F22: segregated_peak_midday_increase, feeds with has_peak_midday_baseline
A23: Feeds with a segregated mode: bus increase larger than segregated-mode increase | B23: =COUNTIFS(feed_data_v2!$AF$2:$AF$1866,TRUE,feed_data_v2!$AI$2:$AI$1866,TRUE) -> 151 | E23: =COUNTIF(feed_data_v2!$AF$2:$AF$1866,TRUE) -> 203 | F23: bus_peak_midday_exceeds_control
A25: Findings:
A26: Timepoint feeds with at least 95% of exact timepoints on a whole minute (Findings para 2) | B26: =COUNTIF(feed_data_v2!$M$2:$M$1866,">=0.95")/E26 -> 0.93684211 | E26: =COUNT(feed_data_v2!$M$2:$M$1866) -> 760 | F26: share_timepoints_whole_minute
A27: Median share of approximate stop times on a whole minute (Findings para 2) | B27: =MEDIAN(feed_data_v2!$N$2:$N$1866) -> 0.10753277 | E27: =COUNT(feed_data_v2!$N$2:$N$1866) -> 712 | F27: share_approx_whole_minute
A28: Feeds with testable approximate times (Findings para 2) | B28: =COUNTIF(feed_data_v2!$P$2:$P$1866,">0") -> 444 | F28: n_approx_testable
A29: Feeds with at least 90% of testable times on the line (Findings para 2) | B29: =COUNTIF(feed_data_v2!$Q$2:$Q$1866,">=0.9") -> 160 | E29: =COUNTIF(feed_data_v2!$P$2:$P$1866,">0") -> 444 | F29: share_approx_on_line
A30: Feeds with testable exact timepoints (Findings para 2) | B30: =COUNTIF(feed_data_v2!$R$2:$R$1866,">0") -> 118 | F30: n_timepoints_testable
A31: Feeds with most stop times flagged approximate and at least 95% of them on whole minutes (Findings para 2) | B31: =COUNTIFS(feed_data_v2!$L$2:$L$1866,">0.5",feed_data_v2!$N$2:$N$1866,">=0.95") -> 213 | E31: =COUNTIF(feed_data_v2!$K$2:$K$1866,"declared") -> 760 | F31: approximate_share, share_approx_whole_minute
A32: Feeds with at least 20 qualifying segments (Findings para 3) | B32: =COUNTIF(feed_data_v2!$Z$2:$Z$1866,">=20") -> 1546 | F32: n_bus_peak_midday_segments
A33: Feeds with a segregated mode (Findings para 3) | B33: =COUNTIF(feed_data_v2!$AF$2:$AF$1866,TRUE) -> 203 | F33: has_peak_midday_baseline
A34: Feeds with a segregated mode: median bus trips a day (Findings para 3) | B34: {=MEDIAN(IF(feed_data_v2!$AF$2:$AF$1866=TRUE,feed_data_v2!$D$2:$D$1866))} -> 7104 | E34: =COUNTIF(feed_data_v2!$AF$2:$AF$1866,TRUE) -> 203 | F34: n_bus_trips, feeds with has_peak_midday_baseline
A35: All 1,546 feeds: median bus trips a day (Findings para 3) | B35: {=MEDIAN(IF(feed_data_v2!$Z$2:$Z$1866>=20,feed_data_v2!$D$2:$D$1866))} -> 533.5 | E35: =COUNTIF(feed_data_v2!$Z$2:$Z$1866,">=20") -> 1546 | F35: n_bus_trips, feeds with n_bus_peak_midday_segments >= 20
A36: Feeds with a segregated mode: median bus increase per segment, seconds (Findings para 3) | B36: {=MEDIAN(IF(feed_data_v2!$AF$2:$AF$1866=TRUE,feed_data_v2!$AB$2:$AB$1866))} -> 1.8183407 | E36: =COUNTIF(feed_data_v2!$AF$2:$AF$1866,TRUE) -> 203 | F36: bus_peak_midday_s, feeds with has_peak_midday_baseline
A37: Feeds written to the second: median inter-stop travel time, seconds (Findings para 4) | B37: {=MEDIAN(IF(feed_data_v2!$I$2:$I$1866<0.05,feed_data_v2!$G$2:$G$1866))} -> 53 | E37: =COUNTIF(feed_data_v2!$I$2:$I$1866,"<0.05") -> 389 | F37: median_travel_time_s, feeds with share_travel_times_whole_minute < 0.05

Sheet feed_data_v2
A1: feed_id | B1: agency | C1: country | D1: n_bus_trips | E1: n_travel_times | F1: n_distinct_travel_times | G1: median_travel_time_s | H1: temporal_resolution_s | I1: share_travel_times_whole_minute | J1: share_stop_times_whole_minute | K1: timepoint_status | L1: approximate_share | M1: share_timepoints_whole_minute | N1: share_approx_whole_minute | O1: interpolation_basis | P1: n_approx_testable | Q1: share_approx_on_line | R1: n_timepoints_testable | S1: share_timepoints_on_line | T1: n_control_modes | U1: has_control_baseline | V1: bus_peak_to_peak_s | W1: segregated_peak_to_peak_s | X1: bus_exceeds_own_control | Y1: share_blank_stop_times | Z1: n_bus_peak_midday_segments | AA1: bus_peak_midday_increase | AB1: bus_peak_midday_s | AC1: bus_am_midday_increase | AD1: bus_pm_midday_increase | AE1: n_control_modes_peak_midday | AF1: has_peak_midday_baseline | AG1: segregated_peak_midday_increase | AH1: segregated_peak_midday_s | AI1: bus_peak_midday_exceeds_control
A2: jbda-aichi-miyoshicity-sansanbus | B2: みよし市 | C2: JP | D2: 92 | E2: 2831 | F2: 10 | G2: 60 | H2: 60 | I2: 1 | J2: 1 | K2: not_declared | P2: 0 | R2: 0 | T2: 0 | U2: FALSE | Y2: 0 | Z2: 176 | AA2: 0.014906832 | AB2: 1.6363636 | AC2: 0.083333333 | AE2: 0 | AF2: FALSE
A3: jbda-akashicity-tacobustacobusmini | B3: 明石市 | C3: JP | D3: 229 | E3: 4262 | F3: 9 | G3: 60 | H3: 60 | I3: 1 | J3: 1 | K3: not_declared | P3: 0 | R3: 0 | T3: 0 | U3: FALSE | V3: 0 | Y3: 0 | Z3: 261 | AA3: 0.014293635 | AB3: 1.4110564 | AC3: 0.018315018 | AD3: -0.014211886 | AE3: 0 | AF3: FALSE
A4: jbda-anjocity-AnkuruBus | B4: 安城市 | C4: JP | D4: 126 | E4: 2758 | F4: 10 | G4: 60 | H4: 60 | I4: 1 | J4: 1 | K4: not_declared | P4: 0 | R4: 0 | T4: 0 | U4: FALSE | Y4: 0 | Z4: 42 | AA4: 0.012707722 | AB4: 1.547619 | AE4: 0 | AF4: FALSE
A5: jbda-annakacity-annakashi-rosenbus | B5: 安中市 | C5: JP | D5: 58 | E5: 1912 | F5: 5 | G5: 60 | H5: 60 | I5: 1 | J5: 1 | K5: not_declared | P5: 0 | R5: 0 | T5: 0 | U5: FALSE | Y5: 0 | Z5: 120 | AA5: 0 | AB5: 0 | AC5: 0 | AD5: 0 | AE5: 0 | AF5: FALSE
A6: jbda-aoi-komaki-aoikotsu | B6: あおい交通 | C6: JP | D6: 147 | E6: 1948 | F6: 13 | G6: 120 | H6: 60 | I6: 1 | J6: 1 | K6: not_declared | P6: 0 | R6: 0 | T6: 0 | U6: FALSE | V6: 12.976744 | Y6: 0 | Z6: 43 | AA6: 0.066148776 | AB6: 10.891473 | AC6: 0.091525424 | AD6: 0.035310734 | AE6: 0 | AF6: FALSE
A7: jbda-ashiyatown-AshiyaTownBus | B7: 芦屋町 | C7: JP | D7: 67 | E7: 925 | F7: 4 | G7: 60 | H7: 60 | I7: 1 | J7: 1 | K7: not_declared | P7: 0 | R7: 0 | T7: 0 | U7: FALSE | V7: 5.4545455 | Y7: 0 | Z7: 25 | AA7: 0.021367521 | AB7: 2 | AC7: 0.076923077 | AD7: 0 | AE7: 0 | AF7: FALSE
A8: jbda-awajicity-awajinawahimebus | B8: 淡路市 | C8: JP | D8: 67 | E8: 3035 | F8: 12 | G8: 60 | H8: 60 | I8: 1 | J8: 1 | K8: not_declared | P8: 0 | R8: 0 | T8: 0 | U8: FALSE | Y8: 0 | Z8: 177 | AA8: 0 | AB8: 0 | AC8: 0 | AD8: 0 | AE8: 0 | AF8: FALSE
A9: jbda-buzencity-BuzenCityBus | B9: 豊前市 | C9: JP | D9: 63 | E9: 1886 | F9: 4 | G9: 60 | H9: 60 | I9: 1 | J9: 1 | K9: not_declared | P9: 0 | R9: 0 | T9: 0 | U9: FALSE | V9: 0 | Y9: 0 | Z9: 74 | AA9: 0 | AB9: 0 | AC9: 0 | AD9: 0 | AE9: 0 | AF9: FALSE
A10: jbda-chigasakicity-eboshigou | B10: 茅ヶ崎市 | C10: JP | D10: 61 | E10: 2023 | F10: 8 | G10: 60 | H10: 60 | I10: 1 | J10: 1 | K10: not_declared | P10: 0 | R10: 0 | T10: 0 | U10: FALSE | Y10: 0 | Z10: 72 | AA10: 0 | AB10: 0 | AC10: 0 | AD10: 0 | AE10: 0 | AF10: FALSE
A11: jbda-chikuma-bus-rosenbus | B11: 千曲バス株式会社 | C11: JP | D11: 99 | E11: 3979 | F11: 9 | G11: 60 | H11: 60 | I11: 1 | J11: 1 | K11: not_declared | P11: 0 | R11: 0 | T11: 0 | U11: FALSE | Y11: 0 | Z11: 155 | AA11: 0 | AB11: 0 | AC11: 0 | AD11: 0 | AE11: 0 | AF11: FALSE
A12: jbda-chikumacity-chikumajunkanbus | B12: 千曲市 | C12: JP | D12: 62 | E12: 1954 | F12: 8 | G12: 60 | H12: 60 | I12: 1 | J12: 1 | K12: not_declared | P12: 0 | R12: 0 | T12: 0 | U12: FALSE | Y12: 0 | Z12: 24 | AA12: 0 | AB12: 0 | AE12: 0 | AF12: FALSE
A13: jbda-chiryucity-communitybus | B13: 知立市 | C13: JP | D13: 50 | E13: 1381 | F13: 10 | G13: 60 | H13: 60 | I13: 1 | J13: 1 | K13: not_declared | P13: 0 | R13: 0 | T13: 0 | U13: FALSE | V13: 0 | Y13: 0 | Z13: 90 | AA13: 0.037677305 | AB13: 4.7222222 | AC13: 0 | AD13: 0 | AE13: 0 | AF13: FALSE
A14: jbda-chitabus-chitabus | B14: 知多乗合（知多バス） | C14: JP | D14: 258 | E14: 3841 | F14: 19 | G14: 60 | H14: 60 | I14: 1 | J14: 1 | K14: not_declared | P14: 0 | R14: 0 | T14: 0 | U14: FALSE | V14: 5.0847458 | Y14: 0 | Z14: 123 | AA14: 0.034737766 | AB14: 3.6771196 | AC14: 0.063768116 | AD14: 0.020833333 | AE14: 0 | AF14: FALSE
A15: jbda-chitetsu-chitetsubus | B15: 富山地方鉄道 | C15: JP | D15: 851 | E15: 18512 | F15: 26 | G15: 60 | H15: 60 | I15: 1 | J15: 1 | K15: not_declared | P15: 0 | R15: 0 | T15: 0 | U15: FALSE | Y15: 0 | Z15: 366 | AA15: 0.080285416 | AB15: 7.730323 | AC15: 0.056124608 | AD15: 0.034377053 | AE15: 0 | AF15: FALSE
A16: jbda-chukibus-chukibus | B16: 中紀バス | C16: JP | D16: 50 | E16: 713 | F16: 8 | G16: 60 | H16: 60 | I16: 1 | J16: 1 | K16: not_declared | P16: 0 | R16: 0 | T16: 0 | U16: FALSE | Y16: 0 | Z16: 1 | AA16: 0.11111111 | AB16: 10 | AC16: 0.11111111 | AE16: 0 | AF16: FALSE
A17: jbda-daishinto-Radiant-City | B17: 大新東株式会社 | C17: JP | D17: 208 | E17: 861 | F17: 5 | G17: 60 | H17: 60 | I17: 1 | J17: 1 | K17: not_declared | P17: 0 | R17: 0 | T17: 0 | U17: FALSE | V17: 7.5 | Y17: 0 | Z17: 4 | AA17: 0.076628352 | AB17: 10.344828 | AC17: 0.11111111 | AD17: 0 | AE17: 0 | AF17: FALSE
A18: jbda-enacity-communitybus | B18: 恵那市 | C18: JP | D18: 167 | E18: 3098 | F18: 8 | G18: 60 | H18: 60 | I18: 1 | J18: 1 | K18: not_declared | P18: 0 | R18: 0 | T18: 0 | U18: FALSE | Y18: 0 | Z18: 7 | AA18: 0.027777778 | AB18: 2.8571429 | AE18: 0 | AF18: FALSE
A19: jbda-fujiedacity-gtfsfjed | B19: 藤枝市 | C19: JP | D19: 95 | E19: 1675 | F19: 11 | G19: 60 | H19: 60 | I19: 1 | J19: 1 | K19: not_declared | P19: 0 | R19: 0 | T19: 0 | U19: FALSE | Y19: 0 | Z19: 24 | AA19: 0 | AB19: 0 | AC19: 0 | AE19: 0 | AF19: FALSE
A20: jbda-gifucity-communitybus | B20: 岐阜市 | C20: JP | D20: 196 | E20: 5636 | F20: 8 | G20: 60 | H20: 60 | I20: 1 | J20: 1 | K20: not_declared | P20: 0 | R20: 0 | T20: 0 | U20: FALSE | Y20: 0 | Z20: 46 | AA20: -0.019512195 | AB20: -1.7391304 | AD20: 0 | AE20: 0 | AF20: FALSE
A21: jbda-gujocity-citybus | B21: 郡上市 | C21: JP | D21: 69 | E21: 1558 | F21: 12 | G21: 60 | H21: 60 | I21: 1 | J21: 1 | K21: not_declared | P21: 0 | R21: 0 | T21: 0 | U21: FALSE | Y21: 0 | Z21: 2 | AA21: 0 | AB21: 0 | AE21: 0 | AF21: FALSE
A22: jbda-gunma-otacity-ootacitybus | B22: 太田市 | C22: JP | D22: 97 | E22: 1536 | F22: 11 | G22: 120 | H22: 60 | I22: 1 | J22: 1 | K22: not_declared | P22: 0 | R22: 0 | T22: 0 | U22: FALSE | Y22: 0 | Z22: 54 | AA22: 0.0060273973 | AB22: 0.81481481 | AC22: 0.01754386 | AE22: 0 | AF22: FALSE
A23: jbda-hachinohe-hachinohe-citybus | B23: 八戸市交通部 | C23: JP | D23: 778 | E23: 20360 | F23: 6 | G23: 60 | H23: 60 | I23: 1 | J23: 1 | K23: not_declared | P23: 0 | R23: 0 | T23: 0 | U23: FALSE | V23: 4.8794827 | Y23: 0 | Z23: 663 | AA23: 0.029426047 | AB23: 2.6854485 | AC23: 0.031696256 | AD23: 0.025978778 | AE23: 0 | AF23: FALSE
A24: jbda-hakubavalley-bus-hakubavalley-nagano-jp | B24: HAKUBAVALLEY事務局 | C24: JP | D24: 70 | E24: 535 | F24: 13 | G24: 420 | H24: 60 | I24: 1 | J24: 1 | K24: not_declared | P24: 0 | R24: 0 | T24: 0 | U24: FALSE | V24: 0 | Y24: 0 | Z24: 24 | AA24: 0 | AB24: 0 | AC24: 0 | AD24: 0 | AE24: 0 | AF24: FALSE
A25: jbda-hakusancity-hakusan_bus_meguru | B25: 白山市 | C25: JP | D25: 124 | E25: 2308 | F25: 15 | G25: 60 | H25: 60 | I25: 1 | J25: 1 | K25: not_declared | P25: 0 | R25: 0 | T25: 0 | U25: FALSE | Y25: 0 | Z25: 0 | AE25: 0 | AF25: FALSE
A26: jbda-hashimacity-HashimaCityCommunityBus | B26: 羽島市 | C26: JP | D26: 74 | E26: 1154 | F26: 6 | G26: 120 | H26: 60 | I26: 1 | J26: 1 | K26: not_declared | P26: 0 | R26: 0 | T26: 0 | U26: FALSE | V26: 0 | Y26: 0 | Z26: 20 | AA26: 0 | AB26: 0 | AC26: 0 | AD26: 0 | AE26: 0 | AF26: FALSE
A27: jbda-hidacity-communitybus | B27: 飛騨市 | C27: JP | D27: 89 | E27: 1813 | F27: 14 | G27: 120 | H27: 60 | I27: 1 | J27: 1 | K27: not_declared | P27: 0 | R27: 0 | T27: 0 | U27: FALSE | Y27: 0 | Z27: 8 | AA27: 0 | AB27: 0 | AE27: 0 | AF27: FALSE
A28: jbda-higashiomicity-higasiohmisicommunitybus | B28: 東近江市 | C28: JP | D28: 107 | E28: 2592 | F28: 10 | G28: 60 | H28: 60 | I28: 1 | J28: 1 | K28: not_declared | P28: 0 | R28: 0 | T28: 0 | U28: FALSE | Y28: 0 | Z28: 60 | AA28: 0 | AB28: 0 | AC28: 0 | AE28: 0 | AF28: FALSE
A29: jbda-higashiuratown-communitybus | B29: 東浦町 | C29: JP | D29: 75 | E29: 1448 | F29: 14 | G29: 60 | H29: 60 | I29: 1 | J29: 1 | K29: not_declared | P29: 0 | R29: 0 | T29: 0 | U29: FALSE | Y29: 0 | Z29: 50 | AA29: -0.0075 | AB29: -0.9 | AC29: 0 | AE29: 0 | AF29: FALSE
A30: jbda-himejicity-ieshima-boze-yukihiko | B30: 姫路市 | C30: JP | D30: 55 | E30: 785 | F30: 10 | G30: 60 | H30: 60 | I30: 1 | J30: 1 | K30: not_declared | P30: 0 | R30: 0 | T30: 0 | U30: FALSE | Y30: 0 | Z30: 10 | AA30: -0.057971014 | AB30: -8 | AE30: 0 | AF30: FALSE
A31: jbda-hiranaitown-hiranaitownbus | B31: 平内町 | C31: JP | D31: 51 | E31: 1236 | F31: 8 | G31: 60 | H31: 60 | I31: 1 | J31: 1 | K31: not_declared | P31: 0 | R31: 0 | T31: 0 | U31: FALSE | Y31: 0 | Z31: 0 | AE31: 0 | AF31: FALSE
A32: jbda-hirosakicity-hokusei-noriai | B32: 弘前市 | C32: JP | D32: 82 | E32: 977 | F32: 7 | G32: 60 | H32: 60 | I32: 1 | J32: 1 | K32: not_declared | P32: 0 | R32: 0 | T32: 0 | U32: FALSE | Y32: 0 | Z32: 0 | AE32: 0 | AF32: FALSE
A33: jbda-hisayamatown-HisayamaIkoBus | B33: 久山町 | C33: JP | D33: 86 | E33: 1668 | F33: 9 | G33: 60 | H33: 60 | I33: 1 | J33: 1 | K33: not_declared | P33: 0 | R33: 0 | T33: 0 | U33: FALSE | V33: 0 | Y33: 0 | Z33: 36 | AA33: -0.0027100271 | AB33: -0.27777778 | AC33: 0 | AD33: -0.002020202 | AE33: 0 | AF33: FALSE
A34: jbda-hokushin-bus-hokushinbus | B34: 北振バス株式会社 | C34: JP | D34: 73 | E34: 1787 | F34: 6 | G34: 60 | H34: 60 | I34: 1 | J34: 1 | K34: not_declared | P34: 0 | R34: 0 | T34: 0 | U34: FALSE | Y34: 0 | Z34: 0 | AE34: 0 | AF34: FALSE
A35: jbda-hyogo-kamikawatown-communitybus | B35: 神河町 | C35: JP | D35: 74 | E35: 1596 | F35: 7 | G35: 60 | H35: 60 | I35: 1 | J35: 1 | K35: not_declared | P35: 0 | R35: 0 | T35: 0 | U35: FALSE | Y35: 0 | Z35: 8 | AA35: -0.035714286 | AB35: -2.5 | AD35: -0.1 | AE35: 0 | AF35: FALSE
A36: jbda-hyogo-ono-ranranbus | B36: 小野市 | C36: JP | D36: 69 | E36: 1267 | F36: 7 | G36: 120 | H36: 60 | I36: 1 | J36: 1 | K36: not_declared | P36: 0 | R36: 0 | T36: 0 | U36: FALSE | V36: 0 | Y36: 0 | Z36: 0 | AE36: 0 | AF36: FALSE
A37: jbda-ibigawatown-communitybus | B37: 揖斐川町 | C37: JP | D37: 72 | E37: 961 | F37: 10 | G37: 60 | H37: 60 | I37: 1 | J37: 1 | K37: not_declared | P37: 0 | R37: 0 | T37: 0 | U37: FALSE | V37: 0 | Y37: 0 | Z37: 12 | AA37: 0 | AB37: 0 | AC37: 0 | AD37: 0 | AE37: 0 | AF37: FALSE
A38: jbda-ichinosekicity-Ichinosekibus | B38: 一関市 | C38: JP | D38: 153 | E38: 4211 | F38: 10 | G38: 60 | H38: 60 | I38: 1 | J38: 1 | K38: not_declared | P38: 0 | R38: 0 | T38: 0 | U38: FALSE | V38: 0 | Y38: 0 | Z38: 21 | AA38: 0 | AB38: 0 | AD38: 0 | AE38: 0 | AF38: FALSE
A39: jbda-igacity-communitybus | B39: 伊賀市 | C39: JP | D39: 100 | E39: 2469 | F39: 9 | G39: 60 | H39: 60 | I39: 1 | J39: 1 | K39: not_declared | P39: 0 | R39: 0 | T39: 0 | U39: FALSE | Y39: 0 | Z39: 0 | AE39: 0 | AF39: FALSE
A40: jbda-imizucity-imizushi | B40: 射水市 | C40: JP | D40: 66 | E40: 1628 | F40: 13 | G40: 60 | H40: 60 | I40: 1 | J40: 1 | K40: not_declared | P40: 0 | R40: 0 | T40: 0 | U40: FALSE | Y40: 0 | Z40: 34 | AA40: 0 | AB40: 0 | AE40: 0 | AF40: FALSE
...
